<?xml version="1.0" encoding="UTF-8"?>
<testsuites>
	<testsuite errors="1" failures="0" name="openid.tests.test_views.BasicTestCase-20190326094909" skipped="0" tests="1" time="0.088" timestamp="2019-03-26T09:49:09">
		<testcase classname="openid.tests.test_views.BasicTestCase" name="test_oauth_flow" time="0.088" timestamp="2019-03-26T09:49:09">
			<error message="Unknown issuer" type="ValueError">
<![CDATA[Traceback (most recent call last):
  File "/vagrant/backend/openid/tests/test_views.py", line 65, in test_oauth_flow
    response = self.client.get('{url}?{query}'.format(url=reverse('openid:callback'), query=query))
  File "/home/vagrant/.local/lib/python3.6/site-packages/django/test/client.py", line 536, in get
    **extra)
  File "/home/vagrant/.local/lib/python3.6/site-packages/django/test/client.py", line 340, in get
    return self.generic('GET', path, secure=secure, **r)
  File "/home/vagrant/.local/lib/python3.6/site-packages/django/test/client.py", line 416, in generic
    return self.request(**r)
  File "/home/vagrant/.local/lib/python3.6/site-packages/django/test/client.py", line 501, in request
    six.reraise(*exc_info)
  File "/home/vagrant/.local/lib/python3.6/site-packages/django/utils/six.py", line 686, in reraise
    raise value
  File "/home/vagrant/.local/lib/python3.6/site-packages/django/core/handlers/exception.py", line 41, in inner
    response = get_response(request)
  File "/home/vagrant/.local/lib/python3.6/site-packages/django/core/handlers/base.py", line 187, in _get_response
    response = self.process_exception_by_middleware(e, request)
  File "/home/vagrant/.local/lib/python3.6/site-packages/django/core/handlers/base.py", line 185, in _get_response
    response = wrapped_callback(request, *callback_args, **callback_kwargs)
  File "/home/vagrant/.local/lib/python3.6/site-packages/django/views/generic/base.py", line 68, in view
    return self.dispatch(request, *args, **kwargs)
  File "/home/vagrant/.local/lib/python3.6/site-packages/django/views/generic/base.py", line 88, in dispatch
    return handler(request, *args, **kwargs)
  File "/vagrant/backend/openid/views.py", line 89, in get
    request_args=request_args
  File "/home/vagrant/.local/lib/python3.6/site-packages/oic/oic/__init__.py", line 674, in do_access_token_request
    authn_method, **kwargs)
  File "/home/vagrant/.local/lib/python3.6/site-packages/oic/oauth2/__init__.py", line 738, in do_access_token_request
    http_args=http_args, **kwargs)
  File "/home/vagrant/.local/lib/python3.6/site-packages/oic/oauth2/__init__.py", line 661, in request_and_return
    **kwargs)
  File "/home/vagrant/.local/lib/python3.6/site-packages/oic/oauth2/__init__.py", line 615, in parse_request_response
    state, **kwargs)
  File "/home/vagrant/.local/lib/python3.6/site-packages/oic/oauth2/__init__.py", line 542, in parse_response
    verf = resp.verify(**kwargs)
  File "/home/vagrant/.local/lib/python3.6/site-packages/oic/oic/message.py", line 339, in verify
    self["id_token"] = verify_id_token(self, **kwargs)
  File "/home/vagrant/.local/lib/python3.6/site-packages/oic/oic/message.py", line 288, in verify_id_token
    raise ValueError('Unknown issuer')
ValueError: Unknown issuer
]]>			</error>
		</testcase>
		<system-out>
<![CDATA[https://loginqa.sullissivik.gl/connect/authorize?response_type=code&scope=openid+digitalimik&client_id=magenta&redirect_uri=http%3A%2F%2Ftestserver%2Foid%2Fcallback%2F&state=KyavNb7K7XahLYF7ZA2RKK4IXi1gsb5b&nonce=XGnk5BAdO1m1nf66lE3jeCUt6I4dZkCy
<HttpResponseRedirect status_code=302, "text/html; charset=utf-8", url="https://loginqa.sullissivik.gl/connect/authorize?response_type=code&scope=openid+digitalimik&client_id=magenta&redirect_uri=http%3A%2F%2Ftestserver%2Foid%2Fcallback%2F&state=KyavNb7K7XahLYF7ZA2RKK4IXi1gsb5b&nonce=XGnk5BAdO1m1nf66lE3jeCUt6I4dZkCy">
dict_keys(['oid_state', 'oid_nonce'])
]]>		</system-out>
		<system-err>
<![CDATA[]]>		</system-err>
	</testsuite>
</testsuites>
